Workbook

Sheet 2 states rev
A1: If the prob of observing the signal increases with the state, there is no dominance relationship between F and G (values cross more than once as a function of prior)
A3: A | B3: 1 | D3: Value from F | E3: =B64 -> 0.1228 | G3: Value from G can be better
A4: K | B4: 0.3 | D4: Value from G | E4: =B103 -> 0.108976
A5: c | B5: 0.02 | E5: signals | F5: y | O5: signals | P5: x
C6: state | D6: theta | E6: 0 | F6: 1 | G6: 2 | H6: sum | I6: signal observed prob | K6: prior | N6: state | O6: 0 | P6: 1 | Q6: 2 | R6: sum
B7: G | C7: low | D7: 0.1 | E7: =_xlfn.BINOM.DIST(E$6,2,$D7*$I7,0) -> 0.9216 | F7: =_xlfn.BINOM.DIST(F$6,2,$D7*$I7,0) -> 0.0768 | G7: =_xlfn.BINOM.DIST(G$6,2,$D7*$I7,0) -> 0.0016 | H7: =SUM(E7:G7) -> 1 | I7: 0.4 | K7: =1-K8 -> 0.6 | M7: F | N7: low | O7: =_xlfn.BINOM.DIST(O$6,2,$D7,0) -> 0.81 | P7: =_xlfn.BINOM.DIST(P$6,2,$D7,0) -> 0.18 | Q7: =_xlfn.BINOM.DIST(Q$6,2,$D7,0) -> 0.01 | R7: =SUM(O7:Q7) -> 1
C8: high | D8: 0.7 | E8: =_xlfn.BINOM.DIST(E$6,2,$D8*$I8,0) -> 0.2601 | F8: =_xlfn.BINOM.DIST(F$6,2,$D8*$I8,0) -> 0.4998 | G8: =_xlfn.BINOM.DIST(G$6,2,$D8*$I8,0) -> 0.2401 | H8: =SUM(E8:G8) -> 1 | I8: 0.7 | K8: 0.4 | N8: high | O8: =_xlfn.BINOM.DIST(O$6,2,$D8,0) -> 0.09 | P8: =_xlfn.BINOM.DIST(P$6,2,$D8,0) -> 0.42 | Q8: =_xlfn.BINOM.DIST(Q$6,2,$D8,0) -> 0.49 | R8: =SUM(O8:Q8) -> 1
A10: State dependent garbling matrices are Binomial
B11: =C7 -> low | C11: x | G11: =C8 -> high | H11: x
B12: y | C12: 0 | D12: 1 | E12: 2 | G12: y | H12: 0 | I12: 1 | J12: 2
B13: 0 | C13: =IF($B13<=C$12,_xlfn.BINOM.DIST($B13,C$12,$I$7,0),0) -> 1 | D13: =IF($B13<=D$12,_xlfn.BINOM.DIST($B13,D$12,$I$7,0),0) -> 0.6 | E13: =IF($B13<=E$12,_xlfn.BINOM.DIST($B13,E$12,$I$7,0),0) -> 0.36 | G13: 0 | H13: =IF($G13<=H$12,_xlfn.BINOM.DIST($G13,H$12,$I$8,0),0) -> 1 | I13: =IF($G13<=I$12,_xlfn.BINOM.DIST($G13,I$12,$I$8,0),0) -> 0.3 | J13: =IF($G13<=J$12,_xlfn.BINOM.DIST($G13,J$12,$I$8,0),0) -> 0.09
B14: 1 | C14: =IF($B14<=C$12,_xlfn.BINOM.DIST($B14,C$12,$I$7,0),0) -> 0 | D14: =IF($B14<=D$12,_xlfn.BINOM.DIST($B14,D$12,$I$7,0),0) -> 0.4 | E14: =IF($B14<=E$12,_xlfn.BINOM.DIST($B14,E$12,$I$7,0),0) -> 0.48 | G14: 1 | H14: =IF($G14<=H$12,_xlfn.BINOM.DIST($G14,H$12,$I$8,0),0) -> 0 | I14: =IF($G14<=I$12,_xlfn.BINOM.DIST($G14,I$12,$I$8,0),0) -> 0.7 | J14: =IF($G14<=J$12,_xlfn.BINOM.DIST($G14,J$12,$I$8,0),0) -> 0.42
B15: 2 | C15: =IF($B15<=C$12,_xlfn.BINOM.DIST($B15,C$12,$I$7,0),0) -> 0 | D15: =IF($B15<=D$12,_xlfn.BINOM.DIST($B15,D$12,$I$7,0),0) -> 0 | E15: =IF($B15<=E$12,_xlfn.BINOM.DIST($B15,E$12,$I$7,0),0) -> 0.16 | G15: 2 | H15: =IF($G15<=H$12,_xlfn.BINOM.DIST($G15,H$12,$I$8,0),0) -> 0 | I15: =IF($G15<=I$12,_xlfn.BINOM.DIST($G15,I$12,$I$8,0),0) -> 0 | J15: =IF($G15<=J$12,_xlfn.BINOM.DIST($G15,J$12,$I$8,0),0) -> 0.49
B16: sum | C16: =SUM(C13:C15) -> 1 | D16: =SUM(D13:D15) -> 1 | E16: =SUM(E13:E15) -> 1 | G16: sum | H16: =SUM(H13:H15) -> 1 | I16: =SUM(I13:I15) -> 1 | J16: =SUM(J13:J15) -> 1
B18: LR ratios | C18: =C14/C13 -> 0 | D18: =D14/D13 -> 0.66666667 | E18: =E14/E13 -> 1.3333333 | H18: =H14/H13 -> 0 | I18: =I14/I13 -> 2.3333333 | J18: =J14/J13 -> 4.6666667
C19: =C15/C14 -> #DIV/0! | D19: =D15/D14 -> 0 | E19: =E15/E14 -> 0.33333333 | H19: =H15/H14 -> #DIV/0! | I19: =I15/I14 -> 0 | J19: =J15/J14 -> 1.1666667
D21: {=IF(SUM(IF(D18:E19>=I18:J19,1,0)),"LR dominates", "error")} -> LR dominates
B23: Garbling*F=G
B24: {=MMULT(O7:Q7,TRANSPOSE(C13:E15))} -> 0.9216 | C24: 0.0768 | D24: 0.0016 | E24: =SUM(_xlfn.ANCHORARRAY(B24)) -> 1
B25: {=MMULT(O8:Q8,TRANSPOSE(H13:J15))} -> 0.2601 | C25: 0.4998 | D25: 0.2401 | E25: =SUM(_xlfn.ANCHORARRAY(B25)) -> 1
B28: Blackwell
C29: x
B30: y | C30: 0 | D30: 1 | E30: 2 | H30: F*transpose(P) | L30: F*transpose(P)-G
B31: 0 | C31: 1 | D31: 0.010075 | E31: 0 | H31: {=MMULT(O7:Q8,TRANSPOSE(C31:E33))} -> 0.8118135 | I31: 0.175182 | J31: 0.0130045 | L31: {=E7:G8-_xlfn.ANCHORARRAY(H31)} -> 0.1097865 | M31: -0.098382 | N31: -0.0114045
B32: 1 | C32: 0 | D32: 0.970704 | E32: 0.045528 | H32: 0.0942315 | I32: 0.4300044 | J32: 0.4757641 | L32: 0.1658685 | M32: 0.0697956 | N32: -0.2356641
B33: 2 | C33: =1-SUM(C31:C32) -> 0 | D33: =1-SUM(D31:D32) -> 0.019221 | E33: =1-SUM(E31:E32) -> 0.954472
B34: sum | C34: =SUM(C31:C33) -> 1 | D34: =SUM(D31:D33) -> 1 | E34: =SUM(E31:E33) -> 1
C36: There is a feasible solution to Blackwell.
B39: G | C39: posterior | J39: F | K39: posterior
B40: state | C40: {=E6:G6} -> 0 | D40: 1 | E40: 2 | J40: state | K40: {=O6:Q6} -> 0 | L40: 1 | M40: 2
B41: {=C7:C8} -> low | C41: =E7*$K7/C$44 -> 0.84164384 | D41: =F7*$K7/D$44 -> 0.18731707 | E41: =G7*$K7/E$44 -> 0.0098969072 | J41: {=N7:N8} -> low | K41: =O7*$K7/K$44 -> 0.93103448 | L41: =P7*$K7/L$44 -> 0.39130435 | M41: =Q7*$K7/M$44 -> 0.02970297
B42: high | C42: =E8*$K8/C$44 -> 0.15835616 | D42: =F8*$K8/D$44 -> 0.81268293 | E42: =G8*$K8/E$44 -> 0.99010309 | J42: high | K42: =O8*$K8/K$44 -> 0.068965517 | L42: =P8*$K8/L$44 -> 0.60869565 | M42: =Q8*$K8/M$44 -> 0.97029703
C43: =SUM(C41:C42) -> 1 | D43: =SUM(D41:D42) -> 1 | E43: =SUM(E41:E42) -> 1 | K43: =SUM(K41:K42) -> 1 | L43: =SUM(L41:L42) -> 1 | M43: =SUM(M41:M42) -> 1
B44: predictive | C44: =SUMPRODUCT(E7:E8,$K$7:$K$8) -> 0.657 | D44: =SUMPRODUCT(F7:F8,$K$7:$K$8) -> 0.246 | E44: =SUMPRODUCT(G7:G8,$K$7:$K$8) -> 0.097 | F44: =SUM(C44:E44) -> 1 | J44: predictive | K44: =SUMPRODUCT(O7:O8,$K$7:$K$8) -> 0.522 | L44: =SUMPRODUCT(P7:P8,$K$7:$K$8) -> 0.276 | M44: =SUMPRODUCT(Q7:Q8,$K$7:$K$8) -> 0.202 | N44: =SUM(K44:M44) -> 1
C53: =_xll.PTreeNodeDecision(treeCalc_7!$F$2,5) -> TRUE | D53: =_xll.PTreeNodeProbability(treeCalc_7!$F$2,5) -> 0.522
C54: 0 | D54: =_xll.PTreeNodeValue(treeCalc_7!$F$2,5) -> 0
B55: =$K$44 -> 0.522 | C55: Decision
B56: 0 | C56: =_xll.PTreeNodeValue(treeCalc_7!$F$2,2) -> 0
D57: =$K$41 -> 0.93103448 | E57: =_xll.PTreeNodeProbability(treeCalc_7!$F$2,7) -> 0
D58: =$B$3*$D$7-$B$4 -> -0.2 | E58: =_xll.PTreeNodeValue(treeCalc_7!$F$2,7) -> -0.2
...

Sheet treeCalc_8
A1: Name | B1: G Tree | E1: Ptree1 Compatibility | F1: 3 | H1: Output Label | K1: R-Value Ref. | L1: 100
A2: SheetRef | B2: ='2 states rev'!#REF! -> #REF! | E2: Eval. Function | F2: =_xll.PTreeEvaluate5(B3,$L$11:$L$26,$J$11:$J$26,$K$11:$K$26,$N$11:$N$26,$G$11:$G$26,,L1) -> 402617882
A3: GenInfo | B3: 0,8,1,0,0,Exponential, 0,0,-1,0,-1,-1,.0001 | E3: Creation Version | F3: 8.10.1 | H3: Output Value NF | I3: <NF>
A4: Def. Link | B4: = | E4: Required Version | F4: 5.0.0 | H4: Output Prob NF | I4: Automatic
A5: EXT REFS | B5: 0 | D5: 0 | E5: Recommended Version | F5: 5.0.0 | H5: Input Value NF | I5: <NF>
A6: Def. Form | E6: Last Modified By Version | F6: 8.10.1 | H6: Input Prob NF | I6: Automatic
A7: Calc Macro | E7: Model GUID | F7: 32513541
A8: Highest# | B8: 16
A10: Anchor Cell | B10: Branch Name | C10: bformtype | D10: valformula | E10: pbformula | F10: distribution | G10: cumPayoffFunction | H10: link | I10: ENDNODEFORMULA | J10: VAL | K10: PB | L10: GenInfo | M10: IntRefs | N10: RefRefs | O10: NodeNames | P10: Collapsed
A11: ='2 states rev'!$B$103 -> 0.108976 | B11: =B1 -> G Tree | C11: 0 | I11: DEFAULT | J11: ='2 states rev'!$A$103 -> 0 | K11: ='2 states rev'!$A$102 -> 0 | L11: 1,0,0,3,2,7,12,0,0,0 | M11: 0 | O11: ='2 states rev'!$B$102 -> signal | P11: FALSE
A12: ='2 states rev'!$C$95 -> 0 | B12: 0 | C12: 0 | I12: DEFAULT | J12: ='2 states rev'!$B$95 -> 0 | K12: ='2 states rev'!$B$94 -> 0.657 | L12: 2,0,0,2,3,4,1,0,0 | M12: 0 | O12: ='2 states rev'!$C$94 -> Decision | P12: FALSE
A13: ='2 states rev'!$D$93 -> 0 | B13: reject | C13: 0 | H13: DEFAULT | I13: DEFAULT | J13: ='2 states rev'!$C$93 -> 0 | L13: 4,0,0,0,2,0,0 | M13: 0 | P13: FALSE
A14: ='2 states rev'!$D$99 -> -0.1049863 | B14: adopt | C14: 0 | I14: DEFAULT | J14: ='2 states rev'!$C$99 -> 0 | L14: 1,0,0,2,5,6,2,0,0 | M14: 0 | O14: ='2 states rev'!$D$98 -> Chance | P14: FALSE
A15: ='2 states rev'!$E$97 -> -0.2 | B15: low | C15: 0 | H15: DEFAULT | I15: DEFAULT | J15: ='2 states rev'!$D$97 -> -0.2 | K15: ='2 states rev'!$D$96 -> 0.84164384 | L15: 4,0,0,0,4,0,0 | M15: 0 | P15: FALSE
A16: ='2 states rev'!$E$101 -> 0.4 | B16: high | C16: 0 | H16: DEFAULT | I16: DEFAULT | J16: ='2 states rev'!$D$101 -> 0.4 | K16: ='2 states rev'!$D$100 -> 0.15835616 | L16: 4,0,0,0,4,0,0 | M16: 0 | P16: FALSE
A17: ='2 states rev'!$C$107 -> 0.28760976 | B17: 1 | C17: 0 | I17: DEFAULT | J17: ='2 states rev'!$B$107 -> 0 | K17: ='2 states rev'!$B$106 -> 0.246 | L17: 2,0,0,2,8,9,1,0,0 | M17: 0 | O17: ='2 states rev'!$C$106 -> Decision | P17: FALSE
A18: ='2 states rev'!$D$105 -> 0 | B18: reject | C18: 0 | H18: DEFAULT | I18: DEFAULT | J18: ='2 states rev'!$C$105 -> 0 | L18: 4,0,0,0,7,0,0 | M18: 0 | P18: FALSE
A19: ='2 states rev'!$D$111 -> 0.28760976 | B19: adopt | C19: 0 | I19: DEFAULT | J19: ='2 states rev'!$C$111 -> 0 | L19: 1,0,0,2,10,11,7,0,0 | M19: 0 | O19: ='2 states rev'!$D$110 -> Chance | P19: FALSE
A20: ='2 states rev'!$E$109 -> -0.2 | B20: low | C20: 0 | H20: DEFAULT | I20: DEFAULT | J20: ='2 states rev'!$D$109 -> -0.2 | K20: ='2 states rev'!$D$108 -> 0.18731707 | L20: 4,0,0,0,9,0,0 | M20: 0 | P20: FALSE
A21: ='2 states rev'!$E$113 -> 0.4 | B21: high | C21: 0 | H21: DEFAULT | I21: DEFAULT | J21: ='2 states rev'!$D$113 -> 0.4 | K21: ='2 states rev'!$D$112 -> 0.81268293 | L21: 4,0,0,0,9,0,0 | M21: 0 | P21: FALSE
A22: ='2 states rev'!$C$117 -> 0.39406186 | B22: 2 | C22: 0 | I22: DEFAULT | J22: ='2 states rev'!$B$117 -> 0 | K22: ='2 states rev'!$B$116 -> 0.097 | L22: 2,0,0,2,13,14,1,0,0 | M22: 0 | O22: ='2 states rev'!$C$116 -> Decision | P22: FALSE
A23: ='2 states rev'!$D$115 -> 0 | B23: reject | C23: 0 | H23: DEFAULT | I23: DEFAULT | J23: ='2 states rev'!$C$115 -> 0 | L23: 4,0,0,0,12,0,0 | M23: 0 | P23: FALSE
A24: ='2 states rev'!$D$121 -> 0.39406186 | B24: adopt | C24: 0 | I24: DEFAULT | J24: ='2 states rev'!$C$121 -> 0 | L24: 1,0,0,2,15,16,12,0,0 | M24: 0 | O24: ='2 states rev'!$D$120 -> Chance | P24: FALSE
A25: ='2 states rev'!$E$119 -> -0.2 | B25: low | C25: 0 | H25: DEFAULT | I25: DEFAULT | J25: ='2 states rev'!$D$119 -> -0.2 | K25: ='2 states rev'!$D$118 -> 0.0098969072 | L25: 4,0,0,0,14,0,0 | M25: 0 | P25: FALSE
A26: ='2 states rev'!$E$123 -> 0.4 | B26: high | C26: 0 | H26: DEFAULT | I26: DEFAULT | J26: ='2 states rev'!$D$123 -> 0.4 | K26: ='2 states rev'!$D$122 -> 0.99010309 | L26: 4,0,0,0,14,0,0 | M26: 0 | P26: FALSE

Sheet treeCalc_7
A1: Name | B1: F tree | E1: Ptree1 Compatibility | F1: 3 | H1: Output Label | K1: R-Value Ref. | L1: 100
A2: SheetRef | B2: ='2 states rev'!#REF! -> #REF! | E2: Eval. Function | F2: =_xll.PTreeEvaluate5(B3,$L$11:$L$26,$J$11:$J$26,$K$11:$K$26,$N$11:$N$26,$G$11:$G$26,,L1) -> 402643609
A3: GenInfo | B3: 0,7,1,0,0,Exponential, 0,0,-1,0,-1,-1,.0001 | E3: Creation Version | F3: 8.10.1 | H3: Output Value NF | I3: <NF>
A4: Def. Link | B4: = | E4: Required Version | F4: 5.0.0 | H4: Output Prob NF | I4: Automatic
A5: EXT REFS | B5: 0 | D5: 0 | E5: Recommended Version | F5: 5.0.0 | H5: Input Value NF | I5: <NF>
A6: Def. Form | E6: Last Modified By Version | F6: 8.10.1 | H6: Input Prob NF | I6: Automatic
A7: Calc Macro | E7: Model GUID | F7: 118C9354
A8: Highest# | B8: 16
A10: Anchor Cell | B10: Branch Name | C10: bformtype | D10: valformula | E10: pbformula | F10: distribution | G10: cumPayoffFunction | H10: link | I10: ENDNODEFORMULA | J10: VAL | K10: PB | L10: GenInfo | M10: IntRefs | N10: RefRefs | O10: NodeNames | P10: Collapsed
A11: ='2 states rev'!$B$64 -> 0.1228 | B11: =B1 -> F tree | C11: 0 | I11: DEFAULT | J11: ='2 states rev'!$A$64 -> 0 | K11: ='2 states rev'!$A$63 -> 0 | L11: 1,0,0,3,2,3,4,0,0,0 | M11: 0 | O11: ='2 states rev'!$B$63 -> signal | P11: FALSE
A12: ='2 states rev'!$C$56 -> 0 | B12: 0 | C12: 0 | I12: DEFAULT | J12: ='2 states rev'!$B$56 -> 0 | K12: ='2 states rev'!$B$55 -> 0.522 | L12: 2,0,0,2,5,6,1,0,0 | M12: 0 | O12: ='2 states rev'!$C$55 -> Decision | P12: FALSE
A13: ='2 states rev'!$C$68 -> 0.16521739 | B13: 1 | C13: 0 | I13: DEFAULT | J13: ='2 states rev'!$B$68 -> 0 | K13: ='2 states rev'!$B$67 -> 0.276 | L13: 2,0,0,2,9,10,1,0,0 | M13: 0 | O13: ='2 states rev'!$C$67 -> Decision | P13: FALSE
A14: ='2 states rev'!$C$78 -> 0.38217822 | B14: 2 | C14: 0 | I14: DEFAULT | J14: ='2 states rev'!$B$78 -> 0 | K14: ='2 states rev'!$B$77 -> 0.202 | L14: 2,0,0,2,13,14,1,0,0 | M14: 0 | O14: ='2 states rev'!$C$77 -> Decision | P14: FALSE
A15: ='2 states rev'!$D$54 -> 0 | B15: reject | C15: 0 | H15: DEFAULT | I15: DEFAULT | J15: ='2 states rev'!$C$54 -> 0 | L15: 4,0,0,0,2,0,0 | M15: 0 | P15: FALSE
A16: ='2 states rev'!$D$60 -> -0.15862069 | B16: adopt | C16: 0 | I16: DEFAULT | J16: ='2 states rev'!$C$60 -> 0 | L16: 1,0,0,2,7,8,2,0,0 | M16: 0 | O16: ='2 states rev'!$D$59 -> Chance | P16: FALSE
A17: ='2 states rev'!$E$58 -> -0.2 | B17: low | C17: 0 | H17: DEFAULT | I17: DEFAULT | J17: ='2 states rev'!$D$58 -> -0.2 | K17: ='2 states rev'!$D$57 -> 0.93103448 | L17: 4,0,0,0,6,0,0 | M17: 0 | P17: FALSE
A18: ='2 states rev'!$E$62 -> 0.4 | B18: high | C18: 0 | H18: DEFAULT | I18: DEFAULT | J18: ='2 states rev'!$D$62 -> 0.4 | K18: ='2 states rev'!$D$61 -> 0.068965517 | L18: 4,0,0,0,6,0,0 | M18: 0 | P18: FALSE
A19: ='2 states rev'!$D$66 -> 0 | B19: reject | C19: 0 | H19: DEFAULT | I19: DEFAULT | J19: ='2 states rev'!$C$66 -> 0 | L19: 4,0,0,0,3,0,0 | M19: 0 | P19: FALSE
A20: ='2 states rev'!$D$72 -> 0.16521739 | B20: adopt | C20: 0 | I20: DEFAULT | J20: ='2 states rev'!$C$72 -> 0 | L20: 1,0,0,2,11,12,3,0,0 | M20: 0 | O20: ='2 states rev'!$D$71 -> Chance | P20: FALSE
A21: ='2 states rev'!$E$70 -> -0.2 | B21: low | C21: 0 | H21: DEFAULT | I21: DEFAULT | J21: ='2 states rev'!$D$70 -> -0.2 | K21: ='2 states rev'!$D$69 -> 0.39130435 | L21: 4,0,0,0,10,0,0 | M21: 0 | P21: FALSE
A22: ='2 states rev'!$E$74 -> 0.4 | B22: high | C22: 0 | H22: DEFAULT | I22: DEFAULT | J22: ='2 states rev'!$D$74 -> 0.4 | K22: ='2 states rev'!$D$73 -> 0.60869565 | L22: 4,0,0,0,10,0,0 | M22: 0 | P22: FALSE
A23: ='2 states rev'!$D$76 -> 0 | B23: reject | C23: 0 | H23: DEFAULT | I23: DEFAULT | J23: ='2 states rev'!$C$76 -> 0 | L23: 4,0,0,0,4,0,0 | M23: 0 | P23: FALSE
A24: ='2 states rev'!$D$82 -> 0.38217822 | B24: adopt | C24: 0 | I24: DEFAULT | J24: ='2 states rev'!$C$82 -> 0 | L24: 1,0,0,2,15,16,4,0,0 | M24: 0 | O24: ='2 states rev'!$D$81 -> Chance | P24: FALSE
A25: ='2 states rev'!$E$80 -> -0.2 | B25: low | C25: 0 | H25: DEFAULT | I25: DEFAULT | J25: ='2 states rev'!$D$80 -> -0.2 | K25: ='2 states rev'!$D$79 -> 0.02970297 | L25: 4,0,0,0,14,0,0 | M25: 0 | P25: FALSE
A26: ='2 states rev'!$E$84 -> 0.4 | B26: high | C26: 0 | H26: DEFAULT | I26: DEFAULT | J26: ='2 states rev'!$D$84 -> 0.4 | K26: ='2 states rev'!$D$83 -> 0.97029703 | L26: 4,0,0,0,14,0,0 | M26: 0 | P26: FALSE
